Workbook

Sheet Дашборд
B2: ⚡ ГИБРИДНЫЙ КОНДОР v2 — ТОРГОВЫЙ ДАШБОРД
B3: SBER | BUY PUT 305 / SELL PUT 315 / BUY CALL 320 / SELL CALL 330 + Акции SBER
B5: 📋 ТЕКУЩАЯ ПОЗИЦИЯ | D5: 📊 РЫНОЧНЫЕ ДАННЫЕ (вводить вручную каждый день)
B6: BUY PUT страйк | C6: 305 | D6: Дата | E6: =СЕГОДНЯ() | F6: Авто
B7: SELL PUT страйк | C7: 315 | D7: Close | E7: 317.2 | F7: Цена закрытия акции SBER
B8: BUY CALL страйк | C8: 320 | D8: High | E8: 319.85 | F8: Максимум дня акции SBER
B9: SELL CALL страйк | C9: 330 | D9: Low | E9: 314.1 | F9: Минимум дня акции SBER
B10: Акции (шт.) | C10: 1000 | D10: PrevClose | E10: 316.4 | F10: Закрытие вчера (акция SBER)
B11: Цена входа акций | C11: 317.2 | D11: IV (%) | E11: 8.9 | F11: Implied Vol ATM-опцион (%)
B12: Центр-страйк | C12: 317
B13: Дата экспирации | C13: 09.05.2026
B15: 🔢 РАСЧЁТНЫЕ ПОКАЗАТЕЛИ (автоматически)
B16: R = High − Low | C16: =E8-E9 | D16: РЕЖИМ РЫНКА | E16: =ЕСЛИ(И(C16<6;ABS(C17)<3;C18<3);"🟢 ФЛЭТ",ЕСЛИ(ИЛИ(C16>10;C17>6);"🔴 ТРЕНД ВВЕРХ",ЕСЛИ(ИЛИ(C16>10;C17<-6);"🔴 ТРЕНД ВНИЗ";"🟡 НЕОПРЕД.")))
B17: Momentum | C17: =E7-E10 | D17: Продавать CALL? | E17: =ЕСЛИ(И(C16<6;ABS(C17)<3;C18<3);"✅ ДА — продавать CALL 320";"❌ НЕТ — ждать")
B18: Δ (откл. от центра) | C18: =ABS(E7-C12) | D18: Продавать PUT? | E18: =ЕСЛИ(И(C16<6;C17>-2;C18<3);"✅ ДА — продавать PUT 315";"❌ НЕТ — ждать")
B20: ⚡ ФАЗА 2 — ROLL ATM CALL (откуп 330 + продажа 315)
B21: Флэт-дней (введи вручную) | C21: 0 | D21: Активировать Roll? | E21: =ЕСЛИ(C21>=8;"🚀 АКТИВИРОВАТЬ ROLL: откуп 330, продажа 315";"⏳ Ждать ещё "&(8-C21)&" дней флэта")
B23: 💰 P&L ПОЗИЦИИ
B24: Пр. CALL 320 (введи) | C24: 0 | D24: ▶ Вводить премию от продажи каждой ноги
B25: Пр. PUT 315 (введи) | C25: 0
B26: Пр. откуп CALL 330 | C26: 0
B27: Пр. продажи CALL 315 | C27: 0
B28: Пр. пут-спреда | C28: 0
B29: 📊 ИТОГО P&L (руб.) | C29: =СУММ(C24:C28) | D29: P&L % | E29: =ЕСЛИ(C11*C10<>0;C29/(C11*C10)*100;0)
B31: 🚫 ЖЁСТКИЕ ЗАПРЕТЫ
B32: ❌ R > 12 руб → | C32: НЕ ТОРГОВАТЬ сегодня
B33: ❌ После падения > 10 руб → | C33: НЕ продавать PUT 2 дня
B34: ❌ После роста > 10 руб → | C34: НЕ продавать CALL 1-2 дня
B35: ❌ Перед новостями → | C35: НЕ открывать новые позиции
B36: ❌ Цена у страйка → | C36: Частично закрыть позицию
B38: 📌 ТЕКУЩАЯ СТРАТЕГИЯ
B39: РЕЖИМ | C39: =E16
B40: ФАЗА | C40: =ЕСЛИ(C21>=8;"ФАЗА 2 (Roll)";"ФАЗА 1 (Кондор)")
B41: ДЕЙСТВИЕ CALL | C41: =E17
B42: ДЕЙСТВИЕ PUT | C42: =E18
B43: ROLL ATM | C43: =E21
B44: Выход при P&L | C44: ≥70% или за 2 дня до экспирации
B46: ℹ️ Close/High/Low/PrevClose = ДНЕВНЫЕ цены акции SBER. IV = имплайд-волатильность ATM-опциона на SBER.
B48: 🔘 КНОПКИ (подключить через Alt+F11 → Вставить модуль → вставить код с листа 'VBA_Макрос')
B49: Кнопка «Обновить данные» | C49: Копирует текущие данные Дашборда в следующую строку Журнала
...

Sheet Журнал
B1: 📒 ЕЖЕДНЕВНЫЙ ЖУРНАЛ ТОРГОВЛИ — SBER Гибридный Кондор v2
B2: Дата | C2: РЫНОЧНЫЕ ДАННЫЕ (акция SBER) | H2: РАСЧЁТЫ | K2: РЕЖИМ | L2: СИГНАЛЫ | N2: P&L (руб.)
C3: Close | D3: High | E3: Low | F3: Prev Close | G3: IV % | H3: R=H-L | I3: Momentum | J3: Δ центр | L3: CALL? | M3: PUT? | N3: Пр.CALL | O3: Пр.PUT | P3: Итого
H4: =ЕСЛИ(ЕПУСТО(D4);"";D4-E4) | I4: =ЕСЛИ(ЕПУСТО(C4);"";C4-F4) | J4: =ЕСЛИ(ЕПУСТО(C4);"";ABS(C4-Дашборд!C12)) | K4: =ЕСЛИ(ЕПУСТО(C4);"";ЕСЛИ(И(H4<6;ABS(I4)<3;J4<3);"ФЛЭТ";ЕСЛИ(ИЛИ(H4>10;I4>6);"ТРЕНД ▲";ЕСЛИ(ИЛИ(H4>10;I4<-6);"ТРЕНД ▼";"НЕОПРЕД.")))) | L4: =ЕСЛИ(ЕПУСТО(C4);"";ЕСЛИ(И(H4<6;ABS(I4)<3;J4<3);"✅ ДА";"❌ НЕТ")) | M4: =ЕСЛИ(ЕПУСТО(C4);"";ЕСЛИ(И(H4<6;I4>-2;J4<3);"✅ ДА";"❌ НЕТ")) | P4: =ЕСЛИ(И(ЕПУСТО(N4);ЕПУСТО(O4));0;СУММ(N4:O4))
H5: =ЕСЛИ(ЕПУСТО(D5);"";D5-E5) | I5: =ЕСЛИ(ЕПУСТО(C5);"";C5-F5) | J5: =ЕСЛИ(ЕПУСТО(C5);"";ABS(C5-Дашборд!C12)) | K5: =ЕСЛИ(ЕПУСТО(C5);"";ЕСЛИ(И(H5<6;ABS(I5)<3;J5<3);"ФЛЭТ";ЕСЛИ(ИЛИ(H5>10;I5>6);"ТРЕНД ▲";ЕСЛИ(ИЛИ(H5>10;I5<-6);"ТРЕНД ▼";"НЕОПРЕД.")))) | L5: =ЕСЛИ(ЕПУСТО(C5);"";ЕСЛИ(И(H5<6;ABS(I5)<3;J5<3);"✅ ДА";"❌ НЕТ")) | M5: =ЕСЛИ(ЕПУСТО(C5);"";ЕСЛИ(И(H5<6;I5>-2;J5<3);"✅ ДА";"❌ НЕТ")) | P5: =ЕСЛИ(И(ЕПУСТО(N5);ЕПУСТО(O5));0;СУММ(N5:O5))
H6: =ЕСЛИ(ЕПУСТО(D6);"";D6-E6) | I6: =ЕСЛИ(ЕПУСТО(C6);"";C6-F6) | J6: =ЕСЛИ(ЕПУСТО(C6);"";ABS(C6-Дашборд!C12)) | K6: =ЕСЛИ(ЕПУСТО(C6);"";ЕСЛИ(И(H6<6;ABS(I6)<3;J6<3);"ФЛЭТ";ЕСЛИ(ИЛИ(H6>10;I6>6);"ТРЕНД ▲";ЕСЛИ(ИЛИ(H6>10;I6<-6);"ТРЕНД ▼";"НЕОПРЕД.")))) | L6: =ЕСЛИ(ЕПУСТО(C6);"";ЕСЛИ(И(H6<6;ABS(I6)<3;J6<3);"✅ ДА";"❌ НЕТ")) | M6: =ЕСЛИ(ЕПУСТО(C6);"";ЕСЛИ(И(H6<6;I6>-2;J6<3);"✅ ДА";"❌ НЕТ")) | P6: =ЕСЛИ(И(ЕПУСТО(N6);ЕПУСТО(O6));0;СУММ(N6:O6))
H7: =ЕСЛИ(ЕПУСТО(D7);"";D7-E7) | I7: =ЕСЛИ(ЕПУСТО(C7);"";C7-F7) | J7: =ЕСЛИ(ЕПУСТО(C7);"";ABS(C7-Дашборд!C12)) | K7: =ЕСЛИ(ЕПУСТО(C7);"";ЕСЛИ(И(H7<6;ABS(I7)<3;J7<3);"ФЛЭТ";ЕСЛИ(ИЛИ(H7>10;I7>6);"ТРЕНД ▲";ЕСЛИ(ИЛИ(H7>10;I7<-6);"ТРЕНД ▼";"НЕОПРЕД.")))) | L7: =ЕСЛИ(ЕПУСТО(C7);"";ЕСЛИ(И(H7<6;ABS(I7)<3;J7<3);"✅ ДА";"❌ НЕТ")) | M7: =ЕСЛИ(ЕПУСТО(C7);"";ЕСЛИ(И(H7<6;I7>-2;J7<3);"✅ ДА";"❌ НЕТ")) | P7: =ЕСЛИ(И(ЕПУСТО(N7);ЕПУСТО(O7));0;СУММ(N7:O7))
H8: =ЕСЛИ(ЕПУСТО(D8);"";D8-E8) | I8: =ЕСЛИ(ЕПУСТО(C8);"";C8-F8) | J8: =ЕСЛИ(ЕПУСТО(C8);"";ABS(C8-Дашборд!C12)) | K8: =ЕСЛИ(ЕПУСТО(C8);"";ЕСЛИ(И(H8<6;ABS(I8)<3;J8<3);"ФЛЭТ";ЕСЛИ(ИЛИ(H8>10;I8>6);"ТРЕНД ▲";ЕСЛИ(ИЛИ(H8>10;I8<-6);"ТРЕНД ▼";"НЕОПРЕД.")))) | L8: =ЕСЛИ(ЕПУСТО(C8);"";ЕСЛИ(И(H8<6;ABS(I8)<3;J8<3);"✅ ДА";"❌ НЕТ")) | M8: =ЕСЛИ(ЕПУСТО(C8);"";ЕСЛИ(И(H8<6;I8>-2;J8<3);"✅ ДА";"❌ НЕТ")) | P8: =ЕСЛИ(И(ЕПУСТО(N8);ЕПУСТО(O8));0;СУММ(N8:O8))
H9: =ЕСЛИ(ЕПУСТО(D9);"";D9-E9) | I9: =ЕСЛИ(ЕПУСТО(C9);"";C9-F9) | J9: =ЕСЛИ(ЕПУСТО(C9);"";ABS(C9-Дашборд!C12)) | K9: =ЕСЛИ(ЕПУСТО(C9);"";ЕСЛИ(И(H9<6;ABS(I9)<3;J9<3);"ФЛЭТ";ЕСЛИ(ИЛИ(H9>10;I9>6);"ТРЕНД ▲";ЕСЛИ(ИЛИ(H9>10;I9<-6);"ТРЕНД ▼";"НЕОПРЕД.")))) | L9: =ЕСЛИ(ЕПУСТО(C9);"";ЕСЛИ(И(H9<6;ABS(I9)<3;J9<3);"✅ ДА";"❌ НЕТ")) | M9: =ЕСЛИ(ЕПУСТО(C9);"";ЕСЛИ(И(H9<6;I9>-2;J9<3);"✅ ДА";"❌ НЕТ")) | P9: =ЕСЛИ(И(ЕПУСТО(N9);ЕПУСТО(O9));0;СУММ(N9:O9))
H10: =ЕСЛИ(ЕПУСТО(D10);"";D10-E10) | I10: =ЕСЛИ(ЕПУСТО(C10);"";C10-F10) | J10: =ЕСЛИ(ЕПУСТО(C10);"";ABS(C10-Дашборд!C12)) | K10: =ЕСЛИ(ЕПУСТО(C10);"";ЕСЛИ(И(H10<6;ABS(I10)<3;J10<3);"ФЛЭТ";ЕСЛИ(ИЛИ(H10>10;I10>6);"ТРЕНД ▲";ЕСЛИ(ИЛИ(H10>10;I10<-6);"ТРЕНД ▼";"НЕОПРЕД.")))) | L10: =ЕСЛИ(ЕПУСТО(C10);"";ЕСЛИ(И(H10<6;ABS(I10)<3;J10<3);"✅ ДА";"❌ НЕТ")) | M10: =ЕСЛИ(ЕПУСТО(C10);"";ЕСЛИ(И(H10<6;I10>-2;J10<3);"✅ ДА";"❌ НЕТ")) | P10: =ЕСЛИ(И(ЕПУСТО(N10);ЕПУСТО(O10));0;СУММ(N10:O10))
H11: =ЕСЛИ(ЕПУСТО(D11);"";D11-E11) | I11: =ЕСЛИ(ЕПУСТО(C11);"";C11-F11) | J11: =ЕСЛИ(ЕПУСТО(C11);"";ABS(C11-Дашборд!C12)) | K11: =ЕСЛИ(ЕПУСТО(C11);"";ЕСЛИ(И(H11<6;ABS(I11)<3;J11<3);"ФЛЭТ";ЕСЛИ(ИЛИ(H11>10;I11>6);"ТРЕНД ▲";ЕСЛИ(ИЛИ(H11>10;I11<-6);"ТРЕНД ▼";"НЕОПРЕД.")))) | L11: =ЕСЛИ(ЕПУСТО(C11);"";ЕСЛИ(И(H11<6;ABS(I11)<3;J11<3);"✅ ДА";"❌ НЕТ")) | M11: =ЕСЛИ(ЕПУСТО(C11);"";ЕСЛИ(И(H11<6;I11>-2;J11<3);"✅ ДА";"❌ НЕТ")) | P11: =ЕСЛИ(И(ЕПУСТО(N11);ЕПУСТО(O11));0;СУММ(N11:O11))
H12: =ЕСЛИ(ЕПУСТО(D12);"";D12-E12) | I12: =ЕСЛИ(ЕПУСТО(C12);"";C12-F12) | J12: =ЕСЛИ(ЕПУСТО(C12);"";ABS(C12-Дашборд!C12)) | K12: =ЕСЛИ(ЕПУСТО(C12);"";ЕСЛИ(И(H12<6;ABS(I12)<3;J12<3);"ФЛЭТ";ЕСЛИ(ИЛИ(H12>10;I12>6);"ТРЕНД ▲";ЕСЛИ(ИЛИ(H12>10;I12<-6);"ТРЕНД ▼";"НЕОПРЕД.")))) | L12: =ЕСЛИ(ЕПУСТО(C12);"";ЕСЛИ(И(H12<6;ABS(I12)<3;J12<3);"✅ ДА";"❌ НЕТ")) | M12: =ЕСЛИ(ЕПУСТО(C12);"";ЕСЛИ(И(H12<6;I12>-2;J12<3);"✅ ДА";"❌ НЕТ")) | P12: =ЕСЛИ(И(ЕПУСТО(N12);ЕПУСТО(O12));0;СУММ(N12:O12))
H13: =ЕСЛИ(ЕПУСТО(D13);"";D13-E13) | I13: =ЕСЛИ(ЕПУСТО(C13);"";C13-F13) | J13: =ЕСЛИ(ЕПУСТО(C13);"";ABS(C13-Дашборд!C12)) | K13: =ЕСЛИ(ЕПУСТО(C13);"";ЕСЛИ(И(H13<6;ABS(I13)<3;J13<3);"ФЛЭТ";ЕСЛИ(ИЛИ(H13>10;I13>6);"ТРЕНД ▲";ЕСЛИ(ИЛИ(H13>10;I13<-6);"ТРЕНД ▼";"НЕОПРЕД.")))) | L13: =ЕСЛИ(ЕПУСТО(C13);"";ЕСЛИ(И(H13<6;ABS(I13)<3;J13<3);"✅ ДА";"❌ НЕТ")) | M13: =ЕСЛИ(ЕПУСТО(C13);"";ЕСЛИ(И(H13<6;I13>-2;J13<3);"✅ ДА";"❌ НЕТ")) | P13: =ЕСЛИ(И(ЕПУСТО(N13);ЕПУСТО(O13));0;СУММ(N13:O13))
H14: =ЕСЛИ(ЕПУСТО(D14);"";D14-E14) | I14: =ЕСЛИ(ЕПУСТО(C14);"";C14-F14) | J14: =ЕСЛИ(ЕПУСТО(C14);"";ABS(C14-Дашборд!C12)) | K14: =ЕСЛИ(ЕПУСТО(C14);"";ЕСЛИ(И(H14<6;ABS(I14)<3;J14<3);"ФЛЭТ";ЕСЛИ(ИЛИ(H14>10;I14>6);"ТРЕНД ▲";ЕСЛИ(ИЛИ(H14>10;I14<-6);"ТРЕНД ▼";"НЕОПРЕД.")))) | L14: =ЕСЛИ(ЕПУСТО(C14);"";ЕСЛИ(И(H14<6;ABS(I14)<3;J14<3);"✅ ДА";"❌ НЕТ")) | M14: =ЕСЛИ(ЕПУСТО(C14);"";ЕСЛИ(И(H14<6;I14>-2;J14<3);"✅ ДА";"❌ НЕТ")) | P14: =ЕСЛИ(И(ЕПУСТО(N14);ЕПУСТО(O14));0;СУММ(N14:O14))
H15: =ЕСЛИ(ЕПУСТО(D15);"";D15-E15) | I15: =ЕСЛИ(ЕПУСТО(C15);"";C15-F15) | J15: =ЕСЛИ(ЕПУСТО(C15);"";ABS(C15-Дашборд!C12)) | K15: =ЕСЛИ(ЕПУСТО(C15);"";ЕСЛИ(И(H15<6;ABS(I15)<3;J15<3);"ФЛЭТ";ЕСЛИ(ИЛИ(H15>10;I15>6);"ТРЕНД ▲";ЕСЛИ(ИЛИ(H15>10;I15<-6);"ТРЕНД ▼";"НЕОПРЕД.")))) | L15: =ЕСЛИ(ЕПУСТО(C15);"";ЕСЛИ(И(H15<6;ABS(I15)<3;J15<3);"✅ ДА";"❌ НЕТ")) | M15: =ЕСЛИ(ЕПУСТО(C15);"";ЕСЛИ(И(H15<6;I15>-2;J15<3);"✅ ДА";"❌ НЕТ")) | P15: =ЕСЛИ(И(ЕПУСТО(N15);ЕПУСТО(O15));0;СУММ(N15:O15))
H16: =ЕСЛИ(ЕПУСТО(D16);"";D16-E16) | I16: =ЕСЛИ(ЕПУСТО(C16);"";C16-F16) | J16: =ЕСЛИ(ЕПУСТО(C16);"";ABS(C16-Дашборд!C12)) | K16: =ЕСЛИ(ЕПУСТО(C16);"";ЕСЛИ(И(H16<6;ABS(I16)<3;J16<3);"ФЛЭТ";ЕСЛИ(ИЛИ(H16>10;I16>6);"ТРЕНД ▲";ЕСЛИ(ИЛИ(H16>10;I16<-6);"ТРЕНД ▼";"НЕОПРЕД.")))) | L16: =ЕСЛИ(ЕПУСТО(C16);"";ЕСЛИ(И(H16<6;ABS(I16)<3;J16<3);"✅ ДА";"❌ НЕТ")) | M16: =ЕСЛИ(ЕПУСТО(C16);"";ЕСЛИ(И(H16<6;I16>-2;J16<3);"✅ ДА";"❌ НЕТ")) | P16: =ЕСЛИ(И(ЕПУСТО(N16);ЕПУСТО(O16));0;СУММ(N16:O16))
H17: =ЕСЛИ(ЕПУСТО(D17);"";D17-E17) | I17: =ЕСЛИ(ЕПУСТО(C17);"";C17-F17) | J17: =ЕСЛИ(ЕПУСТО(C17);"";ABS(C17-Дашборд!C12)) | K17: =ЕСЛИ(ЕПУСТО(C17);"";ЕСЛИ(И(H17<6;ABS(I17)<3;J17<3);"ФЛЭТ";ЕСЛИ(ИЛИ(H17>10;I17>6);"ТРЕНД ▲";ЕСЛИ(ИЛИ(H17>10;I17<-6);"ТРЕНД ▼";"НЕОПРЕД.")))) | L17: =ЕСЛИ(ЕПУСТО(C17);"";ЕСЛИ(И(H17<6;ABS(I17)<3;J17<3);"✅ ДА";"❌ НЕТ")) | M17: =ЕСЛИ(ЕПУСТО(C17);"";ЕСЛИ(И(H17<6;I17>-2;J17<3);"✅ ДА";"❌ НЕТ")) | P17: =ЕСЛИ(И(ЕПУСТО(N17);ЕПУСТО(O17));0;СУММ(N17:O17))
H18: =ЕСЛИ(ЕПУСТО(D18);"";D18-E18) | I18: =ЕСЛИ(ЕПУСТО(C18);"";C18-F18) | J18: =ЕСЛИ(ЕПУСТО(C18);"";ABS(C18-Дашборд!C12)) | K18: =ЕСЛИ(ЕПУСТО(C18);"";ЕСЛИ(И(H18<6;ABS(I18)<3;J18<3);"ФЛЭТ";ЕСЛИ(ИЛИ(H18>10;I18>6);"ТРЕНД ▲";ЕСЛИ(ИЛИ(H18>10;I18<-6);"ТРЕНД ▼";"НЕОПРЕД.")))) | L18: =ЕСЛИ(ЕПУСТО(C18);"";ЕСЛИ(И(H18<6;ABS(I18)<3;J18<3);"✅ ДА";"❌ НЕТ")) | M18: =ЕСЛИ(ЕПУСТО(C18);"";ЕСЛИ(И(H18<6;I18>-2;J18<3);"✅ ДА";"❌ НЕТ")) | P18: =ЕСЛИ(И(ЕПУСТО(N18);ЕПУСТО(O18));0;СУММ(N18:O18))
H19: =ЕСЛИ(ЕПУСТО(D19);"";D19-E19) | I19: =ЕСЛИ(ЕПУСТО(C19);"";C19-F19) | J19: =ЕСЛИ(ЕПУСТО(C19);"";ABS(C19-Дашборд!C12)) | K19: =ЕСЛИ(ЕПУСТО(C19);"";ЕСЛИ(И(H19<6;ABS(I19)<3;J19<3);"ФЛЭТ";ЕСЛИ(ИЛИ(H19>10;I19>6);"ТРЕНД ▲";ЕСЛИ(ИЛИ(H19>10;I19<-6);"ТРЕНД ▼";"НЕОПРЕД.")))) | L19: =ЕСЛИ(ЕПУСТО(C19);"";ЕСЛИ(И(H19<6;ABS(I19)<3;J19<3);"✅ ДА";"❌ НЕТ")) | M19: =ЕСЛИ(ЕПУСТО(C19);"";ЕСЛИ(И(H19<6;I19>-2;J19<3);"✅ ДА";"❌ НЕТ")) | P19: =ЕСЛИ(И(ЕПУСТО(N19);ЕПУСТО(O19));0;СУММ(N19:O19))
H20: =ЕСЛИ(ЕПУСТО(D20);"";D20-E20) | I20: =ЕСЛИ(ЕПУСТО(C20);"";C20-F20) | J20: =ЕСЛИ(ЕПУСТО(C20);"";ABS(C20-Дашборд!C12)) | K20: =ЕСЛИ(ЕПУСТО(C20);"";ЕСЛИ(И(H20<6;ABS(I20)<3;J20<3);"ФЛЭТ";ЕСЛИ(ИЛИ(H20>10;I20>6);"ТРЕНД ▲";ЕСЛИ(ИЛИ(H20>10;I20<-6);"ТРЕНД ▼";"НЕОПРЕД.")))) | L20: =ЕСЛИ(ЕПУСТО(C20);"";ЕСЛИ(И(H20<6;ABS(I20)<3;J20<3);"✅ ДА";"❌ НЕТ")) | M20: =ЕСЛИ(ЕПУСТО(C20);"";ЕСЛИ(И(H20<6;I20>-2;J20<3);"✅ ДА";"❌ НЕТ")) | P20: =ЕСЛИ(И(ЕПУСТО(N20);ЕПУСТО(O20));0;СУММ(N20:O20))
H21: =ЕСЛИ(ЕПУСТО(D21);"";D21-E21) | I21: =ЕСЛИ(ЕПУСТО(C21);"";C21-F21) | J21: =ЕСЛИ(ЕПУСТО(C21);"";ABS(C21-Дашборд!C12)) | K21: =ЕСЛИ(ЕПУСТО(C21);"";ЕСЛИ(И(H21<6;ABS(I21)<3;J21<3);"ФЛЭТ";ЕСЛИ(ИЛИ(H21>10;I21>6);"ТРЕНД ▲";ЕСЛИ(ИЛИ(H21>10;I21<-6);"ТРЕНД ▼";"НЕОПРЕД.")))) | L21: =ЕСЛИ(ЕПУСТО(C21);"";ЕСЛИ(И(H21<6;ABS(I21)<3;J21<3);"✅ ДА";"❌ НЕТ")) | M21: =ЕСЛИ(ЕПУСТО(C21);"";ЕСЛИ(И(H21<6;I21>-2;J21<3);"✅ ДА";"❌ НЕТ")) | P21: =ЕСЛИ(И(ЕПУСТО(N21);ЕПУСТО(O21));0;СУММ(N21:O21))
H22: =ЕСЛИ(ЕПУСТО(D22);"";D22-E22) | I22: =ЕСЛИ(ЕПУСТО(C22);"";C22-F22) | J22: =ЕСЛИ(ЕПУСТО(C22);"";ABS(C22-Дашборд!C12)) | K22: =ЕСЛИ(ЕПУСТО(C22);"";ЕСЛИ(И(H22<6;ABS(I22)<3;J22<3);"ФЛЭТ";ЕСЛИ(ИЛИ(H22>10;I22>6);"ТРЕНД ▲";ЕСЛИ(ИЛИ(H22>10;I22<-6);"ТРЕНД ▼";"НЕОПРЕД.")))) | L22: =ЕСЛИ(ЕПУСТО(C22);"";ЕСЛИ(И(H22<6;ABS(I22)<3;J22<3);"✅ ДА";"❌ НЕТ")) | M22: =ЕСЛИ(ЕПУСТО(C22);"";ЕСЛИ(И(H22<6;I22>-2;J22<3);"✅ ДА";"❌ НЕТ")) | P22: =ЕСЛИ(И(ЕПУСТО(N22);ЕПУСТО(O22));0;СУММ(N22:O22))
H23: =ЕСЛИ(ЕПУСТО(D23);"";D23-E23) | I23: =ЕСЛИ(ЕПУСТО(C23);"";C23-F23) | J23: =ЕСЛИ(ЕПУСТО(C23);"";ABS(C23-Дашборд!C12)) | K23: =ЕСЛИ(ЕПУСТО(C23);"";ЕСЛИ(И(H23<6;ABS(I23)<3;J23<3);"ФЛЭТ";ЕСЛИ(ИЛИ(H23>10;I23>6);"ТРЕНД ▲";ЕСЛИ(ИЛИ(H23>10;I23<-6);"ТРЕНД ▼";"НЕОПРЕД.")))) | L23: =ЕСЛИ(ЕПУСТО(C23);"";ЕСЛИ(И(H23<6;ABS(I23)<3;J23<3);"✅ ДА";"❌ НЕТ")) | M23: =ЕСЛИ(ЕПУСТО(C23);"";ЕСЛИ(И(H23<6;I23>-2;J23<3);"✅ ДА";"❌ НЕТ")) | P23: =ЕСЛИ(И(ЕПУСТО(N23);ЕПУСТО(O23));0;СУММ(N23:O23))
H24: =ЕСЛИ(ЕПУСТО(D24);"";D24-E24) | I24: =ЕСЛИ(ЕПУСТО(C24);"";C24-F24) | J24: =ЕСЛИ(ЕПУСТО(C24);"";ABS(C24-Дашборд!C12)) | K24: =ЕСЛИ(ЕПУСТО(C24);"";ЕСЛИ(И(H24<6;ABS(I24)<3;J24<3);"ФЛЭТ";ЕСЛИ(ИЛИ(H24>10;I24>6);"ТРЕНД ▲";ЕСЛИ(ИЛИ(H24>10;I24<-6);"ТРЕНД ▼";"НЕОПРЕД.")))) | L24: =ЕСЛИ(ЕПУСТО(C24);"";ЕСЛИ(И(H24<6;ABS(I24)<3;J24<3);"✅ ДА";"❌ НЕТ")) | M24: =ЕСЛИ(ЕПУСТО(C24);"";ЕСЛИ(И(H24<6;I24>-2;J24<3);"✅ ДА";"❌ НЕТ")) | P24: =ЕСЛИ(И(ЕПУСТО(N24);ЕПУСТО(O24));0;СУММ(N24:O24))
H25: =ЕСЛИ(ЕПУСТО(D25);"";D25-E25) | I25: =ЕСЛИ(ЕПУСТО(C25);"";C25-F25) | J25: =ЕСЛИ(ЕПУСТО(C25);"";ABS(C25-Дашборд!C12)) | K25: =ЕСЛИ(ЕПУСТО(C25);"";ЕСЛИ(И(H25<6;ABS(I25)<3;J25<3);"ФЛЭТ";ЕСЛИ(ИЛИ(H25>10;I25>6);"ТРЕНД ▲";ЕСЛИ(ИЛИ(H25>10;I25<-6);"ТРЕНД ▼";"НЕОПРЕД.")))) | L25: =ЕСЛИ(ЕПУСТО(C25);"";ЕСЛИ(И(H25<6;ABS(I25)<3;J25<3);"✅ ДА";"❌ НЕТ")) | M25: =ЕСЛИ(ЕПУСТО(C25);"";ЕСЛИ(И(H25<6;I25>-2;J25<3);"✅ ДА";"❌ НЕТ")) | P25: =ЕСЛИ(И(ЕПУСТО(N25);ЕПУСТО(O25));0;СУММ(N25:O25))
H26: =ЕСЛИ(ЕПУСТО(D26);"";D26-E26) | I26: =ЕСЛИ(ЕПУСТО(C26);"";C26-F26) | J26: =ЕСЛИ(ЕПУСТО(C26);"";ABS(C26-Дашборд!C12)) | K26: =ЕСЛИ(ЕПУСТО(C26);"";ЕСЛИ(И(H26<6;ABS(I26)<3;J26<3);"ФЛЭТ";ЕСЛИ(ИЛИ(H26>10;I26>6);"ТРЕНД ▲";ЕСЛИ(ИЛИ(H26>10;I26<-6);"ТРЕНД ▼";"НЕОПРЕД.")))) | L26: =ЕСЛИ(ЕПУСТО(C26);"";ЕСЛИ(И(H26<6;ABS(I26)<3;J26<3);"✅ ДА";"❌ НЕТ")) | M26: =ЕСЛИ(ЕПУСТО(C26);"";ЕСЛИ(И(H26<6;I26>-2;J26<3);"✅ ДА";"❌ НЕТ")) | P26: =ЕСЛИ(И(ЕПУСТО(N26);ЕПУСТО(O26));0;СУММ(N26:O26))
H27: =ЕСЛИ(ЕПУСТО(D27);"";D27-E27) | I27: =ЕСЛИ(ЕПУСТО(C27);"";C27-F27) | J27: =ЕСЛИ(ЕПУСТО(C27);"";ABS(C27-Дашборд!C12)) | K27: =ЕСЛИ(ЕПУСТО(C27);"";ЕСЛИ(И(H27<6;ABS(I27)<3;J27<3);"ФЛЭТ";ЕСЛИ(ИЛИ(H27>10;I27>6);"ТРЕНД ▲";ЕСЛИ(ИЛИ(H27>10;I27<-6);"ТРЕНД ▼";"НЕОПРЕД.")))) | L27: =ЕСЛИ(ЕПУСТО(C27);"";ЕСЛИ(И(H27<6;ABS(I27)<3;J27<3);"✅ ДА";"❌ НЕТ")) | M27: =ЕСЛИ(ЕПУСТО(C27);"";ЕСЛИ(И(H27<6;I27>-2;J27<3);"✅ ДА";"❌ НЕТ")) | P27: =ЕСЛИ(И(ЕПУСТО(N27);ЕПУСТО(O27));0;СУММ(N27:O27))
H28: =ЕСЛИ(ЕПУСТО(D28);"";D28-E28) | I28: =ЕСЛИ(ЕПУСТО(C28);"";C28-F28) | J28: =ЕСЛИ(ЕПУСТО(C28);"";ABS(C28-Дашборд!C12)) | K28: =ЕСЛИ(ЕПУСТО(C28);"";ЕСЛИ(И(H28<6;ABS(I28)<3;J28<3);"ФЛЭТ";ЕСЛИ(ИЛИ(H28>10;I28>6);"ТРЕНД ▲";ЕСЛИ(ИЛИ(H28>10;I28<-6);"ТРЕНД ▼";"НЕОПРЕД.")))) | L28: =ЕСЛИ(ЕПУСТО(C28);"";ЕСЛИ(И(H28<6;ABS(I28)<3;J28<3);"✅ ДА";"❌ НЕТ")) | M28: =ЕСЛИ(ЕПУСТО(C28);"";ЕСЛИ(И(H28<6;I28>-2;J28<3);"✅ ДА";"❌ НЕТ")) | P28: =ЕСЛИ(И(ЕПУСТО(N28);ЕПУСТО(O28));0;СУММ(N28:O28))
H29: =ЕСЛИ(ЕПУСТО(D29);"";D29-E29) | I29: =ЕСЛИ(ЕПУСТО(C29);"";C29-F29) | J29: =ЕСЛИ(ЕПУСТО(C29);"";ABS(C29-Дашборд!C12)) | K29: =ЕСЛИ(ЕПУСТО(C29);"";ЕСЛИ(И(H29<6;ABS(I29)<3;J29<3);"ФЛЭТ";ЕСЛИ(ИЛИ(H29>10;I29>6);"ТРЕНД ▲";ЕСЛИ(ИЛИ(H29>10;I29<-6);"ТРЕНД ▼";"НЕОПРЕД.")))) | L29: =ЕСЛИ(ЕПУСТО(C29);"";ЕСЛИ(И(H29<6;ABS(I29)<3;J29<3);"✅ ДА";"❌ НЕТ")) | M29: =ЕСЛИ(ЕПУСТО(C29);"";ЕСЛИ(И(H29<6;I29>-2;J29<3);"✅ ДА";"❌ НЕТ")) | P29: =ЕСЛИ(И(ЕПУСТО(N29);ЕПУСТО(O29));0;СУММ(N29:O29))
H30: =ЕСЛИ(ЕПУСТО(D30);"";D30-E30) | I30: =ЕСЛИ(ЕПУСТО(C30);"";C30-F30) | J30: =ЕСЛИ(ЕПУСТО(C30);"";ABS(C30-Дашборд!C12)) | K30: =ЕСЛИ(ЕПУСТО(C30);"";ЕСЛИ(И(H30<6;ABS(I30)<3;J30<3);"ФЛЭТ";ЕСЛИ(ИЛИ(H30>10;I30>6);"ТРЕНД ▲";ЕСЛИ(ИЛИ(H30>10;I30<-6);"ТРЕНД ▼";"НЕОПРЕД.")))) | L30: =ЕСЛИ(ЕПУСТО(C30);"";ЕСЛИ(И(H30<6;ABS(I30)<3;J30<3);"✅ ДА";"❌ НЕТ")) | M30: =ЕСЛИ(ЕПУСТО(C30);"";ЕСЛИ(И(H30<6;I30>-2;J30<3);"✅ ДА";"❌ НЕТ")) | P30: =ЕСЛИ(И(ЕПУСТО(N30);ЕПУСТО(O30));0;СУММ(N30:O30))
H31: =ЕСЛИ(ЕПУСТО(D31);"";D31-E31) | I31: =ЕСЛИ(ЕПУСТО(C31);"";C31-F31) | J31: =ЕСЛИ(ЕПУСТО(C31);"";ABS(C31-Дашборд!C12)) | K31: =ЕСЛИ(ЕПУСТО(C31);"";ЕСЛИ(И(H31<6;ABS(I31)<3;J31<3);"ФЛЭТ";ЕСЛИ(ИЛИ(H31>10;I31>6);"ТРЕНД ▲";ЕСЛИ(ИЛИ(H31>10;I31<-6);"ТРЕНД ▼";"НЕОПРЕД.")))) | L31: =ЕСЛИ(ЕПУСТО(C31);"";ЕСЛИ(И(H31<6;ABS(I31)<3;J31<3);"✅ ДА";"❌ НЕТ")) | M31: =ЕСЛИ(ЕПУСТО(C31);"";ЕСЛИ(И(H31<6;I31>-2;J31<3);"✅ ДА";"❌ НЕТ")) | P31: =ЕСЛИ(И(ЕПУСТО(N31);ЕПУСТО(O31));0;СУММ(N31:O31))
H32: =ЕСЛИ(ЕПУСТО(D32);"";D32-E32) | I32: =ЕСЛИ(ЕПУСТО(C32);"";C32-F32) | J32: =ЕСЛИ(ЕПУСТО(C32);"";ABS(C32-Дашборд!C12)) | K32: =ЕСЛИ(ЕПУСТО(C32);"";ЕСЛИ(И(H32<6;ABS(I32)<3;J32<3);"ФЛЭТ";ЕСЛИ(ИЛИ(H32>10;I32>6);"ТРЕНД ▲";ЕСЛИ(ИЛИ(H32>10;I32<-6);"ТРЕНД ▼";"НЕОПРЕД.")))) | L32: =ЕСЛИ(ЕПУСТО(C32);"";ЕСЛИ(И(H32<6;ABS(I32)<3;J32<3);"✅ ДА";"❌ НЕТ")) | M32: =ЕСЛИ(ЕПУСТО(C32);"";ЕСЛИ(И(H32<6;I32>-2;J32<3);"✅ ДА";"❌ НЕТ")) | P32: =ЕСЛИ(И(ЕПУСТО(N32);ЕПУСТО(O32));0;СУММ(N32:O32))
H33: =ЕСЛИ(ЕПУСТО(D33);"";D33-E33) | I33: =ЕСЛИ(ЕПУСТО(C33);"";C33-F33) | J33: =ЕСЛИ(ЕПУСТО(C33);"";ABS(C33-Дашборд!C12)) | K33: =ЕСЛИ(ЕПУСТО(C33);"";ЕСЛИ(И(H33<6;ABS(I33)<3;J33<3);"ФЛЭТ";ЕСЛИ(ИЛИ(H33>10;I33>6);"ТРЕНД ▲";ЕСЛИ(ИЛИ(H33>10;I33<-6);"ТРЕНД ▼";"НЕОПРЕД.")))) | L33: =ЕСЛИ(ЕПУСТО(C33);"";ЕСЛИ(И(H33<6;ABS(I33)<3;J33<3);"✅ ДА";"❌ НЕТ")) | M33: =ЕСЛИ(ЕПУСТО(C33);"";ЕСЛИ(И(H33<6;I33>-2;J33<3);"✅ ДА";"❌ НЕТ")) | P33: =ЕСЛИ(И(ЕПУСТО(N33);ЕПУСТО(O33));0;СУММ(N33:O33))
H34: =ЕСЛИ(ЕПУСТО(D34);"";D34-E34) | I34: =ЕСЛИ(ЕПУСТО(C34);"";C34-F34) | J34: =ЕСЛИ(ЕПУСТО(C34);"";ABS(C34-Дашборд!C12)) | K34: =ЕСЛИ(ЕПУСТО(C34);"";ЕСЛИ(И(H34<6;ABS(I34)<3;J34<3);"ФЛЭТ";ЕСЛИ(ИЛИ(H34>10;I34>6);"ТРЕНД ▲";ЕСЛИ(ИЛИ(H34>10;I34<-6);"ТРЕНД ▼";"НЕОПРЕД.")))) | L34: =ЕСЛИ(ЕПУСТО(C34);"";ЕСЛИ(И(H34<6;ABS(I34)<3;J34<3);"✅ ДА";"❌ НЕТ")) | M34: =ЕСЛИ(ЕПУСТО(C34);"";ЕСЛИ(И(H34<6;I34>-2;J34<3);"✅ ДА";"❌ НЕТ")) | P34: =ЕСЛИ(И(ЕПУСТО(N34);ЕПУСТО(O34));0;СУММ(N34:O34))
H35: =ЕСЛИ(ЕПУСТО(D35);"";D35-E35) | I35: =ЕСЛИ(ЕПУСТО(C35);"";C35-F35) | J35: =ЕСЛИ(ЕПУСТО(C35);"";ABS(C35-Дашборд!C12)) | K35: =ЕСЛИ(ЕПУСТО(C35);"";ЕСЛИ(И(H35<6;ABS(I35)<3;J35<3);"ФЛЭТ";ЕСЛИ(ИЛИ(H35>10;I35>6);"ТРЕНД ▲";ЕСЛИ(ИЛИ(H35>10;I35<-6);"ТРЕНД ▼";"НЕОПРЕД.")))) | L35: =ЕСЛИ(ЕПУСТО(C35);"";ЕСЛИ(И(H35<6;ABS(I35)<3;J35<3);"✅ ДА";"❌ НЕТ")) | M35: =ЕСЛИ(ЕПУСТО(C35);"";ЕСЛИ(И(H35<6;I35>-2;J35<3);"✅ ДА";"❌ НЕТ")) | P35: =ЕСЛИ(И(ЕПУСТО(N35);ЕПУСТО(O35));0;СУММ(N35:O35))
H36: =ЕСЛИ(ЕПУСТО(D36);"";D36-E36) | I36: =ЕСЛИ(ЕПУСТО(C36);"";C36-F36) | J36: =ЕСЛИ(ЕПУСТО(C36);"";ABS(C36-Дашборд!C12)) | K36: =ЕСЛИ(ЕПУСТО(C36);"";ЕСЛИ(И(H36<6;ABS(I36)<3;J36<3);"ФЛЭТ";ЕСЛИ(ИЛИ(H36>10;I36>6);"ТРЕНД ▲";ЕСЛИ(ИЛИ(H36>10;I36<-6);"ТРЕНД ▼";"НЕОПРЕД.")))) | L36: =ЕСЛИ(ЕПУСТО(C36);"";ЕСЛИ(И(H36<6;ABS(I36)<3;J36<3);"✅ ДА";"❌ НЕТ")) | M36: =ЕСЛИ(ЕПУСТО(C36);"";ЕСЛИ(И(H36<6;I36>-2;J36<3);"✅ ДА";"❌ НЕТ")) | P36: =ЕСЛИ(И(ЕПУСТО(N36);ЕПУСТО(O36));0;СУММ(N36:O36))
H37: =ЕСЛИ(ЕПУСТО(D37);"";D37-E37) | I37: =ЕСЛИ(ЕПУСТО(C37);"";C37-F37) | J37: =ЕСЛИ(ЕПУСТО(C37);"";ABS(C37-Дашборд!C12)) | K37: =ЕСЛИ(ЕПУСТО(C37);"";ЕСЛИ(И(H37<6;ABS(I37)<3;J37<3);"ФЛЭТ";ЕСЛИ(ИЛИ(H37>10;I37>6);"ТРЕНД ▲";ЕСЛИ(ИЛИ(H37>10;I37<-6);"ТРЕНД ▼";"НЕОПРЕД.")))) | L37: =ЕСЛИ(ЕПУСТО(C37);"";ЕСЛИ(И(H37<6;ABS(I37)<3;J37<3);"✅ ДА";"❌ НЕТ")) | M37: =ЕСЛИ(ЕПУСТО(C37);"";ЕСЛИ(И(H37<6;I37>-2;J37<3);"✅ ДА";"❌ НЕТ")) | P37: =ЕСЛИ(И(ЕПУСТО(N37);ЕПУСТО(O37));0;СУММ(N37:O37))
H38: =ЕСЛИ(ЕПУСТО(D38);"";D38-E38) | I38: =ЕСЛИ(ЕПУСТО(C38);"";C38-F38) | J38: =ЕСЛИ(ЕПУСТО(C38);"";ABS(C38-Дашборд!C12)) | K38: =ЕСЛИ(ЕПУСТО(C38);"";ЕСЛИ(И(H38<6;ABS(I38)<3;J38<3);"ФЛЭТ";ЕСЛИ(ИЛИ(H38>10;I38>6);"ТРЕНД ▲";ЕСЛИ(ИЛИ(H38>10;I38<-6);"ТРЕНД ▼";"НЕОПРЕД.")))) | L38: =ЕСЛИ(ЕПУСТО(C38);"";ЕСЛИ(И(H38<6;ABS(I38)<3;J38<3);"✅ ДА";"❌ НЕТ")) | M38: =ЕСЛИ(ЕПУСТО(C38);"";ЕСЛИ(И(H38<6;I38>-2;J38<3);"✅ ДА";"❌ НЕТ")) | P38: =ЕСЛИ(И(ЕПУСТО(N38);ЕПУСТО(O38));0;СУММ(N38:O38))
H39: =ЕСЛИ(ЕПУСТО(D39);"";D39-E39) | I39: =ЕСЛИ(ЕПУСТО(C39);"";C39-F39) | J39: =ЕСЛИ(ЕПУСТО(C39);"";ABS(C39-Дашборд!C12)) | K39: =ЕСЛИ(ЕПУСТО(C39);"";ЕСЛИ(И(H39<6;ABS(I39)<3;J39<3);"ФЛЭТ";ЕСЛИ(ИЛИ(H39>10;I39>6);"ТРЕНД ▲";ЕСЛИ(ИЛИ(H39>10;I39<-6);"ТРЕНД ▼";"НЕОПРЕД.")))) | L39: =ЕСЛИ(ЕПУСТО(C39);"";ЕСЛИ(И(H39<6;ABS(I39)<3;J39<3);"✅ ДА";"❌ НЕТ")) | M39: =ЕСЛИ(ЕПУСТО(C39);"";ЕСЛИ(И(H39<6;I39>-2;J39<3);"✅ ДА";"❌ НЕТ")) | P39: =ЕСЛИ(И(ЕПУСТО(N39);ЕПУСТО(O39));0;СУММ(N39:O39))
H40: =ЕСЛИ(ЕПУСТО(D40);"";D40-E40) | I40: =ЕСЛИ(ЕПУСТО(C40);"";C40-F40) | J40: =ЕСЛИ(ЕПУСТО(C40);"";ABS(C40-Дашборд!C12)) | K40: =ЕСЛИ(ЕПУСТО(C40);"";ЕСЛИ(И(H40<6;ABS(I40)<3;J40<3);"ФЛЭТ";ЕСЛИ(ИЛИ(H40>10;I40>6);"ТРЕНД ▲";ЕСЛИ(ИЛИ(H40>10;I40<-6);"ТРЕНД ▼";"НЕОПРЕД.")))) | L40: =ЕСЛИ(ЕПУСТО(C40);"";ЕСЛИ(И(H40<6;ABS(I40)<3;J40<3);"✅ ДА";"❌ НЕТ")) | M40: =ЕСЛИ(ЕПУСТО(C40);"";ЕСЛИ(И(H40<6;I40>-2;J40<3);"✅ ДА";"❌ НЕТ")) | P40: =ЕСЛИ(И(ЕПУСТО(N40);ЕПУСТО(O40));0;СУММ(N40:O40))
...

Sheet Калькулятор
B1: 🔧 КАЛЬКУЛЯТОР СТОИМОСТИ НОГ + ПРОФИЛЬ P&L
B3: 📐 ПАРАМЕТРЫ ЧЕРНОГО-ШОУЛЗА (вводить вручную)
B4: S — Цена акции | C4: 317.2 | D4: Нога | E4: Страйк | F4: Тип | G4: Цена BS | H4: BUY/SELL
B5: σ — Vol (IV, дробь) | C5: 0.089 | D5: BUY PUT 305 | E5: 305 | F5: PUT | G5: =ЕСЛИ($C$8=0;МАКС(E5-$C$4;0);E5*ЕХР(-$C$6*$C$8)*НОРМ.СТ.РАСП(-((ЛН($C$4/E5)+($C$6+$C$5^2/2)*$C$8)/($C$5*КОРЕНЬ($C$8))-$C$5*КОРЕНЬ($C$8));1)-$C$4*НОРМ.СТ.РАСП(-((ЛН($C$4/E5)+($C$6+$C$5^2/2)*$C$8)/($C$5*КОРЕНЬ($C$8)));1)) | H5: BUY
B6: r — Ставка (дробь) | C6: 0.16 | D6: SELL PUT 315 | E6: 315 | F6: PUT | G6: =ЕСЛИ($C$8=0;МАКС(E6-$C$4;0);E6*ЕХР(-$C$6*$C$8)*НОРМ.СТ.РАСП(-((ЛН($C$4/E6)+($C$6+$C$5^2/2)*$C$8)/($C$5*КОРЕНЬ($C$8))-$C$5*КОРЕНЬ($C$8));1)-$C$4*НОРМ.СТ.РАСП(-((ЛН($C$4/E6)+($C$6+$C$5^2/2)*$C$8)/($C$5*КОРЕНЬ($C$8)));1)) | H6: SELL
B7: T — Дней до экспир. | C7: 27 | D7: BUY CALL 320 | E7: 320 | F7: CALL | G7: =ЕСЛИ($C$8=0;МАКС($C$4-E7;0);$C$4*НОРМ.СТ.РАСП((ЛН($C$4/E7)+($C$6+$C$5^2/2)*$C$8)/($C$5*КОРЕНЬ($C$8));1)-E7*ЕХР(-$C$6*$C$8)*НОРМ.СТ.РАСП((ЛН($C$4/E7)+($C$6+$C$5^2/2)*$C$8)/($C$5*КОРЕНЬ($C$8))-$C$5*КОРЕНЬ($C$8);1)) | H7: BUY
B8: T (год) | C8: =C7/365 | D8: SELL CALL 330 | E8: 330 | F8: CALL | G8: =ЕСЛИ($C$8=0;МАКС($C$4-E8;0);$C$4*НОРМ.СТ.РАСП((ЛН($C$4/E8)+($C$6+$C$5^2/2)*$C$8)/($C$5*КОРЕНЬ($C$8));1)-E8*ЕХР(-$C$6*$C$8)*НОРМ.СТ.РАСП((ЛН($C$4/E8)+($C$6+$C$5^2/2)*$C$8)/($C$5*КОРЕНЬ($C$8))-$C$5*КОРЕНЬ($C$8);1)) | H8: SELL
D9: 💰 Дебет конструкции (руб.) | G9: =G5+G7-G6-G8 | H9: руб./акц.
B11: 📈 ПРОФИЛЬ P&L ПО ЦЕНЕ НА ЭКСПИРАЦИИ (100 акций = 1 контракт)
B12: Цена SBER | C12: P&L кондора (руб) | D12: P&L акций (руб) | E12: ИТОГО (руб)
B13: 285 | C13: =((МАКС(305-B13;0)-МАКС(315-B13;0))+(МАКС(B13-320;0)-МАКС(B13-330;0))-$G$9)*100 | D13: =(B13-$C$4)*1000 | E13: =C13+D13
B14: 287.5 | C14: =((МАКС(305-B14;0)-МАКС(315-B14;0))+(МАКС(B14-320;0)-МАКС(B14-330;0))-$G$9)*100 | D14: =(B14-$C$4)*1000 | E14: =C14+D14
B15: 290 | C15: =((МАКС(305-B15;0)-МАКС(315-B15;0))+(МАКС(B15-320;0)-МАКС(B15-330;0))-$G$9)*100 | D15: =(B15-$C$4)*1000 | E15: =C15+D15
B16: 292.5 | C16: =((МАКС(305-B16;0)-МАКС(315-B16;0))+(МАКС(B16-320;0)-МАКС(B16-330;0))-$G$9)*100 | D16: =(B16-$C$4)*1000 | E16: =C16+D16
B17: 295 | C17: =((МАКС(305-B17;0)-МАКС(315-B17;0))+(МАКС(B17-320;0)-МАКС(B17-330;0))-$G$9)*100 | D17: =(B17-$C$4)*1000 | E17: =C17+D17
B18: 297.5 | C18: =((МАКС(305-B18;0)-МАКС(315-B18;0))+(МАКС(B18-320;0)-МАКС(B18-330;0))-$G$9)*100 | D18: =(B18-$C$4)*1000 | E18: =C18+D18
B19: 300 | C19: =((МАКС(305-B19;0)-МАКС(315-B19;0))+(МАКС(B19-320;0)-МАКС(B19-330;0))-$G$9)*100 | D19: =(B19-$C$4)*1000 | E19: =C19+D19
B20: 302.5 | C20: =((МАКС(305-B20;0)-МАКС(315-B20;0))+(МАКС(B20-320;0)-МАКС(B20-330;0))-$G$9)*100 | D20: =(B20-$C$4)*1000 | E20: =C20+D20
B21: 305 | C21: =((МАКС(305-B21;0)-МАКС(315-B21;0))+(МАКС(B21-320;0)-МАКС(B21-330;0))-$G$9)*100 | D21: =(B21-$C$4)*1000 | E21: =C21+D21
B22: 307.5 | C22: =((МАКС(305-B22;0)-МАКС(315-B22;0))+(МАКС(B22-320;0)-МАКС(B22-330;0))-$G$9)*100 | D22: =(B22-$C$4)*1000 | E22: =C22+D22
B23: 310 | C23: =((МАКС(305-B23;0)-МАКС(315-B23;0))+(МАКС(B23-320;0)-МАКС(B23-330;0))-$G$9)*100 | D23: =(B23-$C$4)*1000 | E23: =C23+D23
B24: 312.5 | C24: =((МАКС(305-B24;0)-МАКС(315-B24;0))+(МАКС(B24-320;0)-МАКС(B24-330;0))-$G$9)*100 | D24: =(B24-$C$4)*1000 | E24: =C24+D24
... B39: 350 | C39: =((МАКС(305-B39;0)-МАКС(315-B39;0))+(МАКС(B39-320;0)-МАКС(B39-330;0))-$G$9)*100 | D39: =(B39-$C$4)*1000 | E39: =C39+D39

Sheet Циклы
B1: 📊 ИСТОРИЯ ЦИКЛОВ — БЭКТЕСТ И РЕАЛЬНАЯ ТОРГОВЛЯ
B2: № | C2: Дата входа | D2: Вход | E2: Экспир. | F2: R avg | G2: Режим | H2: Фаза2? | I2: P&L оп. | J2: P&L Roll | K2: Итого | L2: Кумулятив
B3: 1 | C3: 03.04.25 | D3: 03.04.25 | E3: 25.04.25 | F3: 5.2 | G3: ФЛЭТ | H3: ДА | I3: 4200 | J3: 3100 | K3: 7300 | L3: 7300
B4: 2 | C4: 25.04.25 | D4: 25.04.25 | E4: 16.05.25 | F4: 7.8 | G4: НЕОПРЕД | H4: НЕТ | I4: 1800 | J4: 0 | K4: 1800 | L4: 9100
B5: 3 | C5: 16.05.25 | D5: 16.05.25 | E5: 06.06.25 | F5: 4.9 | G5: ФЛЭТ | H5: ДА | I5: 5100 | J5: 4200 | K5: 9300 | L5: 18400
B6: 4 | C6: 06.06.25 | D6: 06.06.25 | E6: 27.06.25 | F6: 6.3 | G6: НЕОПРЕД | H6: НЕТ | I6: 2200 | J6: 0 | K6: 2200 | L6: 20600
B7: 5 | C7: 27.06.25 | D7: 27.06.25 | E7: 18.07.25 | F7: 5.1 | G7: ФЛЭТ | H7: ДА | I7: 4800 | J7: 3800 | K7: 8600 | L7: 29200
B8: 6 | C8: 18.07.25 | D8: 18.07.25 | E8: 08.08.25 | F8: 8.2 | G8: ТРЕНД ▼ | H8: НЕТ | I8: -6476 | J8: 0 | K8: -6476 | L8: 22724
B9: 7 | C9: 08.08.25 | D9: 08.08.25 | E9: 29.08.25 | F9: 4.7 | G9: ФЛЭТ | H9: ДА | I9: 5300 | J9: 4500 | K9: 9800 | L9: 32524
B10: 8 | C10: 29.08.25 | D10: 29.08.25 | E10: 19.09.25 | F10: 5.5 | G10: ФЛЭТ | H10: ДА | I10: 4600 | J10: 3900 | K10: 8500 | L10: 41024
B11: 9 | C11: 19.09.25 | D11: 19.09.25 | E11: 10.10.25 | F11: 6.9 | G11: НЕОПРЕД | H11: НЕТ | I11: 2800 | J11: 0 | K11: 2800 | L11: 43824
B12: 10 | C12: 10.10.25 | D12: 10.10.25 | E12: 31.10.25 | F12: 4.8 | G12: ФЛЭТ | H12: ДА | I12: 5000 | J12: 4100 | K12: 9100 | L12: 52924
B13: 11 | C13: 31.10.25 | D13: 31.10.25 | E13: 21.11.25 | F13: 5 | G13: ФЛЭТ | H13: ДА | I13: 4900 | J13: 4100 | K13: 9000 | L13: 61924
B14: ИТОГО: | J14: =СУММ(J3:J13) | K14: Win Rate:

Sheet Карта решений
B1: 🗺️ КАРТА ПРИНЯТИЯ РЕШЕНИЙ — ЧТО ДЕЛАТЬ В КАЖДОМ РЕЖИМЕ
B2: ДЕЙСТВИЕ | C2: ФЛЭТ | D2: НЕОПРЕД. | E2: ТРЕНД ▲ | F2: ТРЕНД ▼
B5: Вход в кондор (Фаза 1) | C5: ✅ ДА | D5: ⚠️ 50% | E5: ❌ НЕТ | F5: ❌ НЕТ
B6: Держать позицию | C6: ✅ ДА | D6: ✅ ДА | E6: ⚠️ ДА | F6: ⚠️ ДА
B7: Продать CALL | C7: ✅ 50-70% | D7: ❌ НЕТ | E7: ❌ НЕТ | F7: ✅ ДА
B8: Продать PUT | C8: ✅ 50-70% | D8: ❌ НЕТ | E8: ✅ ДА | F8: ❌ НЕТ
B9: Roll: откуп 330, продажа 315 | C9: ✅ Если 8+ дней | D9: ❌ НЕТ | E9: ❌ НЕТ | F9: ❌ НЕТ
B10: Дать акциям расти | C10: ⚠️ ДА | D10: ⚠️ ДА | E10: ✅ ДА | F10: ❌ НЕТ
B11: Сокращать риск | C11: ❌ НЕТ | D11: ⚠️ ЖДАТЬ | E11: ⚠️ ДА | F11: ✅ ДА
B12: Страйк CALL продажи | C12: +10-12 р | D12: +15-20 р | E12: Н/Д | F12: ATM
B13: Страйк PUT продажи | C13: -10-12 р | D13: -15-20 р | E13: ATM | F13: Н/Д
B14: 🚫 ЖЁСТКИЕ ЗАПРЕТЫ
B15: ❌ R > 12 → НЕ ТОРГОВАТЬ
B16: ❌ После падения > 10 р → НЕ продавать PUT 2 дня
B17: ❌ После роста > 10 р → НЕ продавать CALL 1-2 дня
B18: ❌ Перед дивидендами/отчётом → НЕ входить
B19: ❌ Цена у страйка → Частично закрыть позицию
B20: ❌ P&L >= 70% → Закрыть все ноги
B21: ❌ За 2 дня до экспирации → Закрыть ВСЁ
B22: ❌ Объём продажи → НЕ БОЛЕЕ 70% от позиции

Sheet Инструкция
B1: 📖 РУКОВОДСТВО ПОЛЬЗОВАТЕЛЯ — ГИБРИДНЫЙ КОНДОР v2 SBER
B3: 🗂️ СОСТАВ ФАЙЛА
B4: Дашборд: Центральная панель. Вводи рыночные данные, получай сигнал за 10 сек.
B5: Журнал: Ежедневный журнал. Вводи дату + OHLC + IV. Режим и сигналы — авто.
B6: Калькулятор: BS-цены ног + профиль P&L при экспирации. Вводи параметры → авто.
B7: Циклы: История 11 реальных циклов бэктеста. Добавляй новые строки снизу.
B8: Карта решений: Матрица: что делать в каждом режиме. Читай перед торговлей.
B10: 📝 ЕЖЕДНЕВНЫЙ АЛГОРИТМ (9 шагов)
B11: Шаг 1: Открой лист «Дашборд'
B12: Шаг 2: В блоке РЫНОЧНЫЕ ДАННЫЕ введи: Close / High / Low / PrevClose — дневные цены акции SBER. IV — имплайд-волатильность ATM-опциона SBER (из терминала).
B13: Шаг 3: Прочитай ячейку РЕЖИМ РЫНКА: ФЛЭТ / НЕОПРЕД. / ТРЕНД ▲ / ТРЕНД ▼
B14: Шаг 4: Прочитай сигналы: Продавать CALL? / Продавать PUT? → зелёный = действуй
... B48: Google Sheets: ⚠️ Формулы потребуют замены на NORM.S.DIST (английские названия).

Sheet VBA_Макрос
B1: 🔘 КОД VBA ДЛЯ КНОПОК — скопируй в редактор макросов Excel (Alt+F11)
B2: ' ═══════════════════════════════════════════════════
B3: ' КНОПКА 1: "Обновить данные" — копирует E7:E11
B4: ' с листа Дашборд в следующую свободную строку Журнала
B5: ' ═══════════════════════════════════════════════════
B6: Sub ОбновитьДанные()
B7: Dim wsDash As Worksheet
B8: Dim wsJourn As Worksheet
B9: Dim nextRow As Long
B11: Set wsDash = ThisWorkbook.Sheets("Дашборд")
B12: Set wsJourn = ThisWorkbook.Sheets("Журнал")
B14: ' Найти первую пустую строку в Журнале (начиная с 4)
... B107: End Sub
